Workbook
Name _xlfn_SINGLE: none
Name _xlfn_SINGLE: none
Name _xlfn_SINGLE: none

Sheet 01 Overview
A1: GNB master template: internal acts + AOSR
A3: What is inside: 1. Sheets 02-12 = internal acts workbook. 2. Sheets 13-15 = AOSR workbook. 3. This file is a master template for unification and future move to one data layer. 4. It is not wired into runtime yet. How to use: - print selected sheets/pages as needed; - keep this workbook as the analysis and redesign base.

Sheet 02 Acts - Data
A1: ШАБЛОН АКТОВ ГНБ — Лист1 (заполняется ботом)
A2: ИДЕНТИФИКАЦИЯ
A3: Наименование объекта (КЛ ГНБ) | B3: ГНБ 10-1С г. Москва, ул. Кантемировская, д.60
A4: Название стройки / объект | B4: "Строительство улично-дорожной сети с искусственными сооружениями и переустройством инженерных коммуникаций на участке от ул. Маршала Шестопалова до Павелецкого направления Московской железной дороги"
A5: Адрес | B5: По адресу: г. Москва, ул. Кантемировская, д.60
A6: Номер ГНБ перехода | B6: ГНБ № 10-1С
A7: Номер/шифр проекта | B7: ИМ-19-4-Р-3.2Э-ЗП2
A8: Дата начала работ | B8: 01.06.2024 г.
A9: Дата окончания работ | B9: 03.06.2024 г.
A10: Исполнитель (организация) | B10: ООО «Резонанс-Энерго»
A11: Дата завершения работ | B11: 03.06.2024 г.
A13: ОРГАНИЗАЦИИ
A14: Заказчик | B14: ГКУ «УДМС»
A15: Подрядчик | B15: ООО «Резонанс-Энерго»
A16: Проектировщик | B16: АО "МОСИНЖПРОЕКТ"
A18: ПОДПИСАНТЫ
A19: Кто | B19: Описание (организация + должность + ФИО) | C19: Подпись для актов (с чертой)
A20: Подписант 1 (заказчик) | B20: Представитель ЮРЭС АО "ОЭК" | C20: Представитель Южного РЭС АО "ОЭК" ____________________
A21: Подписант 2 (подрядчик) | B21: Начальник участка ООО «Резонанс-Энерго» Борков Е.А | C21: Начальник участка ООО «Резонанс-Энерго» ______________________Борков Е.А
A22: Подписант 3 (опцион.) | C22: Инженер-геодезист ООО «Резонанс-Энерго» ______________________Минаков Н.А.
A23: Тех.надзор (= подп. 1?) | B23: Представитель Южного РЭС АО "ОЭК" и АО "ОЭК"
A24: Подписант 3: если пусто — не печатается на листах
A25: ТРУБА
A26: Марка трубы (полная, с паспортом) | B26: Труба "ПЭ тип "С" 110*6,3 техническая (L012) (паспорт качества от 23.08.2021г.)
A27: Диаметр трубы | B27: d=110 мм.
A29: ПАРАМЕТРЫ ГНБ
A30: Номер ГНБ | B30: L план | C30: L профиль | D30: Кол-во труб | E30: L трубы | F30: d скв | G30: Конфигурация | H30: Стыки
A31: ГНБ № 10-1С | B31: 40.81 | C31: 42.96 | D31: 2 | E31: =C31*D31 -> 85.92 | F31: 300 | G31: 2тр. D=110мм. | H31: =E31/13 -> 6.6092308
A32: ↑ Данные из этой таблицы используются в АОСР

Sheet 03 Acts - Breakdown
B1: Заказчик: | C1: ='02 Acts - Data'!B14 -> ГКУ «УДМС»
B2: Подрядчик: | C2: ='02 Acts - Data'!B15 -> ООО «Резонанс-Энерго»
B3: Объект: | C3: ='02 Acts - Data'!B4 -> "Строительство улично-дорожной сети с искусственными сооружениями и переустройством инженерных коммуникаций на участке от ул. Маршала Шестопалова до Павелецкого направления Московской железной дороги"
B4: Дата: | C4: ='02 Acts - Data'!B11 -> 03.06.2024 г.
A6: АКТ
A7: разбивки закрытого перехода методом ГНБ
A9: Комиссия в составе представителей:
A11: Инженер-геодезист ООО "Резонанс-Энерго" Минаков Н.А.
A12: ='02 Acts - Data'!B21 -> Начальник участка ООО «Резонанс-Энерго» Борков Е.А
A13: Представитель ЮРЭС АО "ОЭК"
A14: составили настоящий акт о том, что произведена геодезическая разбивка закрытого перехода | J14: ='02 Acts - Data'!B6 -> ГНБ № 10-1С
A15: выполняемого методом ГНБ | D15: ='02 Acts - Data'!B5 -> По адресу: г. Москва, ул. Кантемировская, д.60
A17: Выполнены следующие работы:
A18: -привязка и разбивка приемного и рабочего котлованов к зданиям и сооружениям;
A19: -геодезическая разбивка осей перехода;
A21: Геодезические работы на устройство закрытого перехода | F21: ='02 Acts - Data'!B6 -> ГНБ № 10-1С | I21: методом ГНБ выполнены
A22: в соответствии с СП 126.13330.2017 Геодезические работы в строительстве.
A28: ='02 Acts - Data'!C21 -> Начальник участка ООО «Резонанс-Энерго» ______________________Борков Е.А
A31: ='02 Acts - Data'!C22 -> Инженер-геодезист ООО «Резонанс-Энерго» ______________________Минаков Н.А.
A33: Представитель ЮРЭС АО "ОЭК" ________________

Sheet 04 Acts - Sealing
B1: Заказчик: | C1: ='02 Acts - Data'!B14 -> ГКУ «УДМС»
B2: Генподрядчик: | C2: ='02 Acts - Data'!B15 -> ООО «Резонанс-Энерго»
B3: Объект: | C3: ='02 Acts - Data'!B4 -> "Строительство улично-дорожной сети с искусственными сооружениями и переустройством инженерных коммуникаций на участке от ул. Маршала Шестопалова до Павелецкого направления Московской железной дороги"
B4: Дата: | C4: ='02 Acts - Data'!B11 -> 03.06.2024 г.
A6: АКТ
A7: герметизации концов труб закрытого перехода
A9: Комиссия в составе представителей:
A11: ='02 Acts - Data'!B20 -> Представитель ЮРЭС АО "ОЭК"
A12: ='02 Acts - Data'!B21 -> Начальник участка ООО «Резонанс-Энерго» Борков Е.А
A14: Произвела осмотр работ выполненных | E14: ='02 Acts - Data'!B10 -> ООО «Резонанс-Энерго»
A15: и составила настоящий акт о нижеследующем:
A16: 1. К освидетельствованию и приемке предъявлены следующие работы
A17: Герметизация концов труб закрытого перехода | F17: ='02 Acts - Data'!B6 -> ГНБ № 10-1С | I17: выполненного методом ГНБ
A18: Расположенного | C18: ='02 Acts - Data'!B5 -> По адресу: г. Москва, ул. Кантемировская, д.60
A20: 2. Работы выполнены по проекту | D20: ='02 Acts - Data'!B16 -> АО "МОСИНЖПРОЕКТ" | G20: Шифр: | H20: ='02 Acts - Data'!B7 -> ИМ-19-4-Р-3.2Э-ЗП2
A22: 3. При выполнении работ применены заглушки | E22: ='02 Acts - Data'!B27 -> d=110 мм.
A24: 4. Дата начала работ | D24: ='02 Acts - Data'!B8 -> 01.06.2024 г.
A26: 5. Дата окончания работ | D26: ='02 Acts - Data'!B9 -> 03.06.2024 г.
A28: РЕШЕНИЕ КОМИССИИ
A29: Работы выполнены в соответствии с проектом, стандартами, строительными нормами и отвечают требованиям их приемки.
A30: На основании изложенного разрешается обратная засыпка приемного и рабочего котлована строительным песком.
A35: ='02 Acts - Data'!C20 -> Представитель Южного РЭС АО "ОЭК" ____________________
A37: ='02 Acts - Data'!C21 -> Начальник участка ООО «Резонанс-Энерго» ______________________Борков Е.А

Sheet 05 Acts - AOSR
B1: Заказчик: | C1: ='02 Acts - Data'!B14 -> ГКУ «УДМС»
B2: Генподрядчик: | C2: ='02 Acts - Data'!B15 -> ООО «Резонанс-Энерго»
B3: Объект: | C3: ='02 Acts - Data'!B4 -> "Строительство улично-дорожной сети с искусственными сооружениями и переустройством инженерных коммуникаций на участке от ул. Маршала Шестопалова до Павелецкого направления Московской железной дороги"
B4: Дата: | C4: ='02 Acts - Data'!B11 -> 03.06.2024 г.
A6: АКТ
A7: На скрытые работы закрытого перехода выполненного методом ГНБ
A9: Комиссия в составе представителей:
A11: ='02 Acts - Data'!B20 -> Представитель ЮРЭС АО "ОЭК"
A12: ='02 Acts - Data'!B21 -> Начальник участка ООО «Резонанс-Энерго» Борков Е.А
A14: составили настоящий акт о том, что осмотрены выполненные работы по строительству закрытого перехода
A15: ='02 Acts - Data'!B6 -> ГНБ № 10-1С | D15: методом ГНБ | F15: ='02 Acts - Data'!B5 -> По адресу: г. Москва, ул. Кантемировская, д.60
A17: При осмотре установлено:
A18: 1. | B18: Длина закрытого перехода | D18: ='02 Acts - Data'!A31 -> ГНБ № 10-1С | E18: по плану | F18: ='02 Acts - Data'!B31 -> 40.81 | G18: по профилю | H18: ='02 Acts - Data'!C31 -> 42.96
A19: 2 | B19: Количество трубоканалов | D19: ='02 Acts - Data'!A31 -> ГНБ № 10-1С | E19: ='02 Acts - Data'!D31 -> 2
A20: 3 | B20: Общая длина трубоканалов | D20: ='02 Acts - Data'!A31 -> ГНБ № 10-1С | E20: ='02 Acts - Data'!E31 -> 85.92
A21: 4 | B21: Труба марки | D21: ='02 Acts - Data'!B26 -> Труба "ПЭ тип "С" 110*6,3 техническая (L012) (паспорт качества от 23.08.2021г.)
A22: 5 | B22: Заглушки установлены
A23: 6 | B23: Трубоканалы пронумерованы, загерметизированы и проходимы
A24: 7 | B24: Работы выполнены согласно проекта с качеством, удовлетворяющим заказчика
A26: Работы по устройство закрытого перехода | E26: ='02 Acts - Data'!B6 -> ГНБ № 10-1С | H26: методом ГНБ выполнены в соответствии
A27: с СП 48.13330.2019 СНиП 12.01-2004 Организация строительства.
A32: ='02 Acts - Data'!C20 -> Представитель Южного РЭС АО "ОЭК" ____________________
A34: ='02 Acts - Data'!C21 -> Начальник участка ООО «Резонанс-Энерго» ______________________Борков Е.А

Sheet 06 Acts - Supervision
B1: Заказчик: | C1: ='02 Acts - Data'!B14 -> ГКУ «УДМС»
B2: Генподрядчик: | C2: ='02 Acts - Data'!B15 -> ООО «Резонанс-Энерго»
B3: Объект: | C3: ='02 Acts - Data'!B4 -> "Строительство улично-дорожной сети с искусственными сооружениями и переустройством инженерных коммуникаций на участке от ул. Маршала Шестопалова до Павелецкого направления Московской железной дороги"
B4: Дата: | C4: ='02 Acts - Data'!B11 -> 03.06.2024 г.
A6: АКТ
A7: Технического надзора по устройству закрытого перехода методом ГНБ
A9: Комиссия в составе представителей:
A11: ='02 Acts - Data'!B20 -> Представитель ЮРЭС АО "ОЭК"
A12: ='02 Acts - Data'!B21 -> Начальник участка ООО «Резонанс-Энерго» Борков Е.А
A14: Произвела осмотр работ выполненных | E14: ='02 Acts - Data'!B10 -> ООО «Резонанс-Энерго»
A15: 1. Устройство закрытого перехода методом ГНБ | E15: ='02 Acts - Data'!B6 -> ГНБ № 10-1С
A16: производилось под непрерывным техническим надзором персонала
A17: ='02 Acts - Data'!B23 -> Представитель Южного РЭС АО "ОЭК" и АО "ОЭК" | H17: Все технические указания
A18: уполномоченных лиц выполнены в полном объеме в соответствии с правилами устройства закрытых переходов
A19: и производственных инструкций.
A20: Технические хар-ки ГНБ Машины: DDW 36/13 , мощностью, кВт – 140
A21: Качество работ удовлетворительно.
A23: 2. Работы выполнены по проекту | D23: ='02 Acts - Data'!B16 -> АО "МОСИНЖПРОЕКТ" | G23: Шифр: | H23: ='02 Acts - Data'!B7 -> ИМ-19-4-Р-3.2Э-ЗП2
A25: 3. При выполнении работ применены Трубы | E25: ='02 Acts - Data'!B26 -> Труба "ПЭ тип "С" 110*6,3 техническая (L012) (паспорт качества от 23.08.2021г.)
A27: 4. Дата начала работ | D27: ='02 Acts - Data'!B8 -> 01.06.2024 г.
A29: 5. Дата окончания работ | D29: ='02 Acts - Data'!B9 -> 03.06.2024 г.
A31: РЕШЕНИЕ КОМИССИИ
A32: Работы выполнены в соответствии с проектом, стандартами, строительными нормами и отвечают требованиям их приемки.
A33: На основании изложенного разрешается производство последующих работ по прокладке кабельной линии
A37: ='02 Acts - Data'!C20 -> Представитель Южного РЭС АО "ОЭК" ____________________
A39: ='02 Acts - Data'!C21 -> Начальник участка ООО «Резонанс-Энерго» ______________________Борков Е.А

Sheet 07 Acts - Acceptance
B1: Заказчик: | C1: ='02 Acts - Data'!B14 -> ГКУ «УДМС»
B2: Генподрядчик: | C2: ='02 Acts - Data'!B15 -> ООО «Резонанс-Энерго»
B3: Объект: | C3: ='02 Acts - Data'!B4 -> "Строительство улично-дорожной сети с искусственными сооружениями и переустройством инженерных коммуникаций на участке от ул. Маршала Шестопалова до Павелецкого направления Московской железной дороги"
B4: Дата: | C4: ='02 Acts - Data'!B11 -> 03.06.2024 г.
A6: АКТ
A7: технической приемки готового закрытого перехода
A9: Комиссия в составе представителей:
A11: ='02 Acts - Data'!B20 -> Представитель ЮРЭС АО "ОЭК"
A12: ='02 Acts - Data'!B21 -> Начальник участка ООО «Резонанс-Энерго» Борков Е.А
A14: Произвела осмотр работ выполненных | E14: ='02 Acts - Data'!B10 -> ООО «Резонанс-Энерго»
A15: и составила настоящий акт о нижеследующем:
A16: 1. К освидетельствованию и приемке предъявлены следующие работы
A17: устройство закрытого перехода | D17: ='02 Acts - Data'!B6 -> ГНБ № 10-1С | G17: методом ГНБ
A18: ='02 Acts - Data'!B5 -> По адресу: г. Москва, ул. Кантемировская, д.60
A20: 2. Работы выполнены по проекту | D20: ='02 Acts - Data'!B16 -> АО "МОСИНЖПРОЕКТ" | G20: Шифр: | H20: ='02 Acts - Data'!B7 -> ИМ-19-4-Р-3.2Э-ЗП2
A22: 3. Дата начала работ | D22: ='02 Acts - Data'!B8 -> 01.06.2024 г.
A24: 4. Дата окончания работ | D24: ='02 Acts - Data'!B9 -> 03.06.2024 г.
A26: РЕШЕНИЕ КОМИССИИ
A27: Работы выполнены в соответствии с проектом, стандартами, строительными нормами и отвечают требованиям их приемки.
A28: На основании изложенного разрешается производство последующих работ по прокладке кабельной линии
A33: ='02 Acts - Data'!C20 -> Представитель Южного РЭС АО "ОЭК" ____________________
A35: ='02 Acts - Data'!C21 -> Начальник участка ООО «Резонанс-Энерго» ______________________Борков Е.А

Sheet 08 Acts - PP
B1: Заказчик: | C1: ='02 Acts - Data'!B14 -> ГКУ «УДМС»
B2: Генподрядчик: | C2: ='02 Acts - Data'!B15 -> ООО «Резонанс-Энерго»
B3: Объект: | C3: ='02 Acts - Data'!B4 -> "Строительство улично-дорожной сети с искусственными сооружениями и переустройством инженерных коммуникаций на участке от ул. Маршала Шестопалова до Павелецкого направления Московской железной дороги"
B4: Дата: | C4: ='02 Acts - Data'!B11 -> 03.06.2024 г.
A6: АКТ
A7: сдачи-приемки сооружения под прокладку КЛ
A9: Комиссия в составе представителей:
A11: ='02 Acts - Data'!B20 -> Представитель ЮРЭС АО "ОЭК"
A12: ='02 Acts - Data'!B21 -> Начальник участка ООО «Резонанс-Энерго» Борков Е.А
A14: Произвела осмотр работ выполненных | E14: ='02 Acts - Data'!B10 -> ООО «Резонанс-Энерго»
A15: и составила настоящий акт о нижеследующем:
A16: 1. К освидетельствованию и приемке предъявлены следующие работы
A17: Строительство закрытого перехода | D17: ='02 Acts - Data'!B6 -> ГНБ № 10-1С | H17: выполненного методом ГНБ
A18: Расположенного | C18: ='02 Acts - Data'!B5 -> По адресу: г. Москва, ул. Кантемировская, д.60
A20: 2. Работы выполнены по проекту | D20: ='02 Acts - Data'!B16 -> АО "МОСИНЖПРОЕКТ" | G20: Шифр: | H20: ='02 Acts - Data'!B7 -> ИМ-19-4-Р-3.2Э-ЗП2
A22: 3. При выполнении работ применена труба | E22: ='02 Acts - Data'!B26 -> Труба "ПЭ тип "С" 110*6,3 техническая (L012) (паспорт качества от 23.08.2021г.)
A24: 4. При выполнении работ применены заглушки | E24: ='02 Acts - Data'!B27 -> d=110 мм.
A26: 5. Дата начала работ | D26: ='02 Acts - Data'!B8 -> 01.06.2024 г.
A28: 6. Дата окончания работ | D28: ='02 Acts - Data'!B9 -> 03.06.2024 г.
A30: РЕШЕНИЕ КОМИССИИ
A31: Работы выполнены в соответствии с проектом, стандартами, строительными нормами и отвечают требованиям их приемки.
A32: На основании изложенного разрешается производство последующих работ по прокладке кабельной линии
A36: ='02 Acts - Data'!C20 -> Представитель Южного РЭС АО "ОЭК" ____________________
A38: ='02 Acts - Data'!C21 -> Начальник участка ООО «Резонанс-Энерго» ______________________Борков Е.А

Sheet 09 Acts - Inspection
A1: АКТ
A2: освидетельствования скрытых работ
A4: г. Москва | G4: ='02 Acts - Data'!B11 -> 03.06.2024 г.
A6: Сооружение закрытого перехода | F6: ='02 Acts - Data'!B3 -> ГНБ 10-1С г. Москва, ул. Кантемировская, д.60
A7: (наименование работ)
A9: ='02 Acts - Data'!B4 -> "Строительство улично-дорожной сети с искусственными сооружениями и переустройством инженерных коммуникаций на участке от ул. Маршала Шестопалова до Павелецкого направления Московской железной дороги"
A10: (наименование здания, сооружения)
A11: ='02 Acts - Data'!B5 -> По адресу: г. Москва, ул. Кантемировская, д.60
A12: (район застройки, квартал, улица, № дома и корпуса)
A13: Комиссия в составе | C13: ='02 Acts - Data'!B23 -> Представитель Южного РЭС АО "ОЭК" и АО "ОЭК"
A14: представителей: | C14: ='02 Acts - Data'!B20 -> Представитель ЮРЭС АО "ОЭК"
A15: Ф.И.О., организация) | C15: ='02 Acts - Data'!B21 -> Начальник участка ООО «Резонанс-Энерго» Борков Е.А
C16: ='02 Acts - Data'!B22
A18: Произвела осмотр работ выполненных | E18: ='02 Acts - Data'!B10 -> ООО «Резонанс-Энерго»
A19: и составила настоящий акт о нижеследующем:
B20: 1. К освидетельствованию и приемке предъявлены следующие работы_______________________.
A22: Устройство закрытого перехода | F22: ='02 Acts - Data'!B6 -> ГНБ № 10-1С
A23: (наименование скрытых работ)
B24: 2. Работы выполнены по проекту | F24: ='02 Acts - Data'!B7 -> ИМ-19-4-Р-3.2Э-ЗП2
A26: ='02 Acts - Data'!B16 -> АО "МОСИНЖПРОЕКТ"
A27: (проект серии, наименование проектной организации, № чертежей и дата их составления)
B28: 3. При выполнении работ применены следующие материалы:
A29: заглушки 225 мм трубы проходимы; капроновый шнур затянут; заглушки установлены
A30: (наименование материалов, конструкций с указанием марки, типа, категории качества и т.п.)
B31: 4. Дата начала работ | E31: ='02 Acts - Data'!B8 -> 01.06.2024 г.
B33: 5. Дата окончания работ | E33: ='02 Acts - Data'!B9 -> 03.06.2024 г.
A35: РЕШЕНИЕ КОМИССИИ
B37: Работы выполнены в соответствии с проектом, стандартами, строительными нормами и
A38: отвечают требованиям их приемки.
B39: На основании изложенного разрешается производство работ по устройству (монтажу)
A40: прокладку эл. кабеля в закрытый переход
B42: ='02 Acts - Data'!B20 -> Представитель ЮРЭС АО "ОЭК"
B43: ='02 Acts - Data'!B23 -> Представитель Южного РЭС АО "ОЭК" и АО "ОЭК"
B44: ='02 Acts - Data'!B21 -> Начальник участка ООО «Резонанс-Энерго» Борков Е.А
B45: ='02 Acts - Data'!B22

Sheet 10 Acts - Alignment
B1: Заказчик: | C1: ='02 Acts - Data'!B14 -> ГКУ «УДМС»
B2: Генподрядчик: | C2: ='02 Acts - Data'!B15 -> ООО «Резонанс-Энерго»
B3: Объект: | C3: ='02 Acts - Data'!B4 -> "Строительство улично-дорожной сети с искусственными сооружениями и переустройством инженерных коммуникаций на участке от ул. Маршала Шестопалова до Павелецкого направления Московской железной дороги"
B4: Дата: | C4: ='02 Acts - Data'!B11 -> 03.06.2024 г.
A6: АКТ
A7: проверки трубных переходов на соосность
A9: Комиссия в составе представителей:
A11: ='02 Acts - Data'!B20 -> Представитель ЮРЭС АО "ОЭК"
A12: ='02 Acts - Data'!B21 -> Начальник участка ООО «Резонанс-Энерго» Борков Е.А
A14: Произвела осмотр работ выполненных | E14: ='02 Acts - Data'!B10 -> ООО «Резонанс-Энерго»
A15: и составила настоящий акт о нижеследующем:
A16: 1. К освидетельствованию и приемке предъявлены следующие работы
A17: проверка на соосность труб закрытого перехода | F17: ='02 Acts - Data'!B6 -> ГНБ № 10-1С | I17: выполненного методом ГНБ
A18: Расположенного | C18: ='02 Acts - Data'!B5 -> По адресу: г. Москва, ул. Кантемировская, д.60
A20: 2. Работы выполнены по проекту | D20: ='02 Acts - Data'!B16 -> АО "МОСИНЖПРОЕКТ" | G20: Шифр: | H20: ='02 Acts - Data'!B7 -> ИМ-19-4-Р-3.2Э-ЗП2
A22: 3. При выполнении работ применены Трубы | E22: ='02 Acts - Data'!B26 -> Труба "ПЭ тип "С" 110*6,3 техническая (L012) (паспорт качества от 23.08.2021г.)
A24: 4. Дата начала работ | D24: ='02 Acts - Data'!B8 -> 01.06.2024 г.
A26: 5. Дата окончания работ | D26: ='02 Acts - Data'!B9 -> 03.06.2024 г.
A28: РЕШЕНИЕ КОМИССИИ
A29: Работы выполнены в соответствии с проектом, стандартами, строительными нормами и отвечают требованиям их приемки.
A30: На основании изложенного разрешается производство последующих работ по прокладке кабельной линии
A35: ='02 Acts - Data'!C20 -> Представитель Южного РЭС АО "ОЭК" ____________________
A37: ='02 Acts - Data'!C21 -> Начальник участка ООО «Резонанс-Энерго» ______________________Борков Е.А

Sheet 11 Acts - Pipe Welding
B1: Заказчик: | C1: ='02 Acts - Data'!B14 -> ГКУ «УДМС»
B2: Генподрядчик: | C2: ='02 Acts - Data'!B15 -> ООО «Резонанс-Энерго»
B3: Объект: | C3: ='02 Acts - Data'!B4 -> "Строительство улично-дорожной сети с искусственными сооружениями и переустройством инженерных коммуникаций на участке от ул. Маршала Шестопалова до Павелецкого направления Московской железной дороги"
B4: Дата: | C4: ='02 Acts - Data'!B11 -> 03.06.2024 г.
A6: АКТ
A7: сварки трубы
A9: Комиссия в составе представителей:
A11: ='02 Acts - Data'!B20 -> Представитель ЮРЭС АО "ОЭК"
A12: ='02 Acts - Data'!B21 -> Начальник участка ООО «Резонанс-Энерго» Борков Е.А
A13: ='02 Acts - Data'!B22
A14: Произвела осмотр работ выполненных | E14: ='02 Acts - Data'!B10 -> ООО «Резонанс-Энерго»
A15: и составила настоящий акт о нижеследующем:
A16: 1. К освидетельствованию и приемке предъявлены следующие работы
A17: сварка плетей труб для закрытого перехода | E17: ='02 Acts - Data'!B6 -> ГНБ № 10-1С | H17: выполняемого методом ГНБ
A18: Расположенного | C18: ='02 Acts - Data'!B5 -> По адресу: г. Москва, ул. Кантемировская, д.60
A20: 2. Количество предъявляемых сварочных стыков: | E20: ='02 Acts - Data'!H31 -> 6.6092308
A22: 3. Работы выполнены по проекту | D22: ='02 Acts - Data'!B16 -> АО "МОСИНЖПРОЕКТ" | G22: Шифр: | H22: ='02 Acts - Data'!B7 -> ИМ-19-4-Р-3.2Э-ЗП2
A24: 4. При выполнении работ применены Трубы | E24: ='02 Acts - Data'!B26 -> Труба "ПЭ тип "С" 110*6,3 техническая (L012) (паспорт качества от 23.08.2021г.)
A26: 5. Дата начала работ | D26: ='02 Acts - Data'!B8 -> 01.06.2024 г.
A28: 6. Дата окончания работ | D28: ='02 Acts - Data'!B9 -> 03.06.2024 г.
A30: РЕШЕНИЕ КОМИССИИ
A31: Работы выполнены в соответствии с проектом, стандартами, строительными нормами и отвечают требованиям их приемки.
A32: На основании изложенного разрешается затяжка пэ труб в скважину закрытого перехода.
A37: ='02 Acts - Data'!C20 -> Представитель Южного РЭС АО "ОЭК" ____________________
A39: ='02 Acts - Data'!C21 -> Начальник участка ООО «Резонанс-Энерго» ______________________Борков Е.А

Sheet 12 Acts - Inventory
B1: Заказчик: | C1: ='02 Acts - Data'!B14 -> ГКУ «УДМС»
B2: Генподрядчик: | C2: ='02 Acts - Data'!B15 -> ООО «Резонанс-Энерго»
B3: Объект: | C3: ='02 Acts - Data'!B4 -> "Строительство улично-дорожной сети с искусственными сооружениями и переустройством инженерных коммуникаций на участке от ул. Маршала Шестопалова до Павелецкого направления Московской железной дороги"
B4: Дата: | C4: ='02 Acts - Data'!B11 -> 03.06.2024 г.
A6: ИНВЕНТАРНАЯ ОПИСЬ
A7: ЭЛЕМЕНТОВ ЗАКРЫТОГО ПЕРЕХОДА
A8: Закрытый переход | C8: ='02 Acts - Data'!B6 -> ГНБ № 10-1С
A9: Расположенный | C9: ='02 Acts - Data'!B5 -> По адресу: г. Москва, ул. Кантемировская, д.60
A11: ='02 Acts - Data'!A31 -> ГНБ № 10-1С
A12: № п.п. | B12: Материалы | J12: Ед. изм. | K12: Кол-во
A13: 1 | B13: Труба | C13: ='02 Acts - Data'!B26 -> Труба "ПЭ тип "С" 110*6,3 техническая (L012) (паспорт качества от 23.08.2021г.) | J13: м.п. | K13: ='02 Acts - Data'!E31 -> 85.92
A14: 2 | B14: Капроновый шнур | J14: м.п. | K14: =K13 -> 85.92
A15: 3 | B15: Заглушки | C15: ='02 Acts - Data'!B27 -> d=110 мм. | J15: шт | K15: ='02 Acts - Data'!D31*2 -> 4
A20: ='02 Acts - Data'!C23
A22: ='02 Acts - Data'!C21 -> Начальник участка ООО «Резонанс-Энерго» ______________________Борков Е.А | B22: =CONCATENATE("Строительство ",'02 Acts - Data'!B6," методом ГНБ") -> Строительство ГНБ № 10-1С методом ГНБ
A24: ='02 Acts - Data'!C20 -> Представитель Южного РЭС АО "ОЭК" ____________________

Sheet 13 AOSR - Data
A2: переход №
A3: Lпр=
A4: Длина труб= | B4: =C3*B3 -> 0
A5: Адрес
A6: Дата начала | B6: =CONCATENATE(C6," ",D6," ",E6)
A7: Дата окончания | B7: =CONCATENATE(C7," ",D7," ",E7)
A8: Дата АОСР | B8: =CONCATENATE(C8," ",D8," ",E8)

Sheet 14 AOSR - Page 1
AJ1: Приказ Минстроя №344/пр от 16.05.2023
AJ2: приложение №2
A3: Объект капитального строительства
A5: (наименование объекта капитального строительства в соответствии с проектной документацией, почтовый или строительный адрес объекта капитального строительства)
A6: Застройщик, технический заказчик, лицо, ответственное за эксплуатацию здания, сооружения, или региональный оператор
A8: (ФИО, адрес места жительства, ОГРНИП, ИНН индивидуального предпринимателя, полное или сокращенное наименование, ОГРН, ИНН, адрес юр. лица в пределах его нахождения, телефон или факс, полное и (или) сокращенное наименование, ОГРН, ИНН саморегулируемой организации, членом которой является указанное юридическое лицо или индивидуальный предприниматель (за исключением случаев, когда членство в саморегулируемых организациях в области, строительства, реконструкции, капитального ремонта объектов капитального строительства не требуется); ФИО, паспортные данные, адрес места жительства, телефон или факс - для физических лиц, не являющихся индивидуальными предпринимателями)
A9: Лицо, осуществляющее строительство, реконструкцию, капитальный ремонт
A11: (фамилия, имя, отчество (последнее - при наличии), адрес места жительства, ОГРНИП, ИНН индивидуального предпринимателя, полное и (или) сокращенное наименование, ОГРН, ИНН, адрес юридического лица в пределах его местонахождения, телефон или факс, полное или сокращенное наименование, ОГРН, ИНН саморегулируемой организации, членом которой является указанное юр. лицо или индивидуальный предприниматель (за исключением случаев, когда членство в саморегулируемых организациях в области строительства, реконструкции, капитального ремонта объектов капитального строительства не требуется)
A12: Лицо, осуществляющее подготовку проектной документации
A14: (ФИО, адрес места жительства, ОГРНИП, ИНН индивидуального предпринимателя, полное или сокращенное наименование, ОГРН, ИНН, адрес юр. лица в пределах его места нахождения, телефон или факс, полное и (или) сокращенное наименование, ОГРН, ИНН саморегулируемой организации, членом которой является указанное юр. лицо или индивидуальный предприниматель (за исключением случаев, когда членство в саморегулируемых организациях в области архитектурно-строительного проектирования не требуется)
A15: АКТ
A16: разбивки осей объекта капитального строительства на местности
B18: № | C18: =CONCATENATE("1 (ЗП ГНБ №",[1]Лист1!B2,")") -> 1 (ЗП ГНБ №) | X18: " | Y18: =[1]Лист1!C6 -> 0 | AA18: " | AB18: =[1]Лист1!D6 -> 0 | AG18: =[1]Лист1!E6 -> 0 | AJ18: г.
Z19: (дата составления акта)
A21: Представитель застройщика, технического заказчика, лица, ответственного за эксплуатацию здания, сооружения, или регионального оператора по вопросам строительного контроля
A23: Представитель застройщика, технического заказчика, лица, ответственного за эксплуатацию здания, сооружения | AQ23: Акимов Ю.О.
AQ24: Панин Д.А.
A25: (должность (при наличии), фамилия, инициалы, идентификационный номер в национальном реестре специалистов в области строительства (за исключением случаев, когда членство в саморегулируемых организациях в области строительства, реконструкции, капитального ремонта объектов капитального строительства не требуется), реквизиты распорядительного документа, подтверждающего полномочия, с указанием полного или сокращенного наименования, ОГРН, ИНН, адреса юр. лица в пределах его места нахождения , ФИО, адреса места жительства, ОГРНИП, ИНН индивидуального предпринимателя
A26: Представитель лица, осуществляющего строительство, реконструкцию, капитальный ремонт
A28: (должность (при наличии), фамилия, инициалы, реквизиты распорядительного документа, подтверждающего полномочия)
A29: Представитель лица, осуществляющего строительство, реконструкцию, капитальный ремонт, по вопросам строительного контроля
A31: (должность (при наличии), фамилия, инициалы, идентификационный номер в национальном реестре специалистов в области строительства (за исключением случаев, когда членство в саморегулируемых организациях в области строительства, реконструкции, капитального ремонта объектов капитального строительства не требуется), реквизиты распорядительного документа, подтверждающего полномочия)
A32: Представитель лица, осуществляющего подготовку проектной документации (в случае привлечения застройщиком лица, осуществляющего подготовку проектной документации, для проверки соответствия выполняемых работ проектной документации согласно части 2 статьи 53 Градостроительного кодекса Российской Федерации)
A34: (должность (при наличии), фамилия, инициалы, реквизиты распорядительного документа, подтверждающего полномочия, с указанием полного или сокращенного наименования, ОГРН, ИНН, адреса юр. лица в пределах его места нахождения, фамилии, имени, отчества, адреса места жительства, ОГРНИП, ИНН индивидуального предпринимателя)
A35: Представитель лица, выполнившего работы по разбивке осей объекта капитального строительства на местности (в случае выполнения работ по договорам о строительстве, реконcтрукции, капитальном ремонте объектов капитального строительства, заключенным с иными лицами)
A37: (должность (при наличии), фамилия, инициалы, реквизиты распорядительного документа, подтверждающего полномочия, с указанием полного или сокращенного наименования, ОГРН, ИНН, адреса юр. лица в пределах его места нахождения, ФИО, адреса места жительства, ОГРНИП, ИНН индивидуального предпринимателя)
A38: составили настоящий акт о том, что произведена в натуре разбивка осей
A39: =CONCATENATE("Закрытого перехода методом ГНБ №",[1]Лист1!B2," по адресу: ",[1]Лист1!B5,) -> Закрытого перехода методом ГНБ № по адресу:
A40: объекта капитального строительства
A41: =A4 -> 0
A42: (наименование объекта капитального строительства)
A43: При этом установлено:
A44: 1.Разбивка произведена по данным
A46: (номер, другие реквизиты чертежа, наименование проектной документации)
A47: 2. Закрепление осей произведено | N47: колышками разбивки при помощи геодезического оборудования.
A49: 3. Обозначение осей, нумерация и расположение точек соответствует проектной документации.
A51: Разбивка осей объекта капитального строительства на местности соответствует требованиям проектной документации, а также техническим регламентам (нормам и правилам), иным нормативным правовым актам
A52: =CONCATENATE(A45,", ",A41) -> , 0
A53: (номер, другие реквизиты чертежа, наименование проектной документации, сведения о лицах, осуществляющих подготовку
A54: СП 126.13330.2017 «Геодезические работы в строительстве». СНиП 3.01.03-84
...

Sheet 15 AOSR - Page 2
AJ1: Приказ Минстроя №344/пр от 16.05.2023
AJ2: приложение №3
A3: Объект капитального строительства
A4: ='[1]АОСР (1)'!A4:AJ4 -> 0
A5: (наименование объекта капитального строительства в соответствии с проектной документацией, почтовый или строительный адрес объекта капитального строительства)
A6: Застройщик, технический заказчик, лицо, ответственное за эксплуатацию здания, сооружения, или региональный оператор
A7: ='[1]АОСР (1)'!A7:AJ7 -> 0
A8: (ФИО, адрес места жительства, ОГРНИП, ИНН индивидуального предпринимателя, полное или сокращенное наименование, ОГРН, ИНН, адрес юр. лица в пределах его нахождения, телефон или факс, полное и (или) сокращенное наименование, ОГРН, ИНН саморегулируемой организации, членом которой является указанное юридическое лицо или индивидуальный предприниматель (за исключением случаев, когда членство в саморегулируемых организациях в области, строительства, реконструкции, капитального ремонта объектов капитального строительства не требуется); ФИО, паспортные данные, адрес места жительства, телефон или факс - для физических лиц, не являющихся индивидуальными предпринимателями)
A9: Лицо, осуществляющее строительство, реконструкцию, капитальный ремонт
A10: ='[1]АОСР (1)'!A10:AJ10 -> 0
A11: (фамилия, имя, отчество (последнее - при наличии), адрес места жительства, ОГРНИП, ИНН индивидуального предпринимателя, полное и (или) сокращенное наименование, ОГРН, ИНН, адрес юридического лица в пределах его местонахождения, телефон или факс, полное или сокращенное наименование, ОГРН, ИНН саморегулируемой организации, членом которой является указанное юр. лицо или индивидуальный предприниматель (за исключением случаев, когда членство в саморегулируемых организациях в области строительства, реконструкции, капитального ремонта объектов капитального строительства не требуется)
A12: Лицо, осуществляющее подготовку проектной документации
A13: ='[1]АОСР (1)'!A13:AJ13 -> 0
A14: (ФИО, адрес места жительства, ОГРНИП, ИНН индивидуального предпринимателя, полное или сокращенное наименование, ОГРН, ИНН, адрес юр. лица в пределах его места нахождения, телефон или факс, полное и (или) сокращенное наименование, ОГРН, ИНН саморегулируемой организации, членом которой является указанное юр. лицо или индивидуальный предприниматель (за исключением случаев, когда членство в саморегулируемых организациях в области архитектурно-строительного проектирования не требуется)
A15: АКТ
A16: освидетельствования скрытых работ
B18: № | C18: =CONCATENATE("2 (ЗП ГНБ №",[1]Лист1!B2,")") -> 2 (ЗП ГНБ №) | X18: " | Y18: =[1]Лист1!C8 -> 0 | AA18: " | AB18: =[1]Лист1!D8 -> 0 | AG18: =[1]Лист1!E8 -> 0 | AJ18: г.
Z19: (дата составления акта)
A21: Представитель застройщика, технического заказчика, лица, ответственного за эксплуатацию здания, сооружения, или регионального оператора по вопросам строительного контроля
A22: ='[1]АОСР (1)'!A22:AJ22 -> 0
A23: Представитель застройщика, технического заказчика, лица, ответственного за эксплуатацию здания, сооружения
A24: ='[1]АОСР (1)'!A24:AJ24 -> 0
A25: (должность (при наличии), фамилия, инициалы, идентификационный номер в национальном реестре специалистов в области строительства (за исключением случаев, когда членство в саморегулируемых организациях в области строительства, реконструкции, капитального ремонта объектов капитального строительства не требуется), реквизиты распорядительного документа, подтверждающего полномочия, с указанием полного или сокращенного наименования, ОГРН, ИНН, адреса юр. лица в пределах его места нахождения , ФИО, адреса места жительства, ОГРНИП, ИНН индивидуального предпринимателя
A26: Представитель лица, осуществляющего строительство, реконструкцию, капитальный ремонт
A27: ='[1]АОСР (1)'!A27:AJ27 -> 0
A28: (должность (при наличии), фамилия, инициалы, реквизиты распорядительного документа, подтверждающего полномочия)
A29: Представитель лица, осуществляющего строительство, реконструкцию, капитальный ремонт, по вопросам строительного контроля
A30: ='[1]АОСР (1)'!A30:AJ30 -> 0
A31: (должность (при наличии), фамилия, инициалы, идентификационный номер в национальном реестре специалистов в области строительства (за исключением случаев, когда членство в саморегулируемых организациях в области строительства, реконструкции, капитального ремонта объектов капитального строительства не требуется), реквизиты распорядительного документа, подтверждающего полномочия)
A32: Представитель лица, осуществляющего подготовку проектной документации (в случае привлечения застройщиком лица, осуществляющего подготовку проектной документации, для проверки соответствия выполняемых работ проектной документации согласно части 2 статьи 53 Градостроительного кодекса Российской Федерации)
A34: (должность (при наличии), фамилия, инициалы, реквизиты распорядительного документа, подтверждающего полномочия, с указанием полного или сокращенного наименования, ОГРН, ИНН, адреса юр. лица в пределах его места нахождения, фамилии, имени, отчества, адреса места жительства, ОГРНИП, ИНН индивидуального предпринимателя)
A35: Представитель лица, выполнившего работы, подлежащие освидетельствованию (в случае выполнения работ по договорам о строительстве, реконcтрукции, капитальном ремонте объектов капитального строительства, заключенным с иными лицами)
A37: (должность (при наличии), фамилия, инициалы, реквизиты распорядительного документа, подтверждающего полномочия, с указанием полного или сокращенного наименования, ОГРН, ИНН, адреса юр. лица в пределах его места нахождения, ФИО, адреса места жительства, ОГРНИП, ИНН индивидуального предпринимателя)
A38: произвели осмотр работ, выполненных
A40: (полное и (или) сокращенное наименование или ФИО лица, выполнившего работы, подлежащие освидетельствованию)
A41: и составили настоящий акт о нижеследующем:
A42: 1. К освидетельствованию предъявлены следующие работы:
A43: =CONCATENATE("Строительство закрытого перехода №",[1]Лист1!B2," методом ГНБ; Lпр.=",[1]Лист1!B3," м, Lобщ.=",[1]Лист1!B4," м, одна скважина из 2-х труб d=225 мм, по адресу : ",[1]Лист1!B5,", проверка трубных переходов на проходимость; затягивание шнура; нумерация труб; установка заглушек.") -> Строительство закрытого перехода № методом ГНБ; Lпр.= м, Lобщ.=0 м, одна скважина из 2-х труб d=225 мм, по адресу : , проверка трубных переходов на проходимость; затягивание шнура; нумерация труб; установка заглушек.
A44: (наименование скрытых работ)
A45: 2. Работы выполнены по проектной документации
...
