Workbook

Sheet Лист1
A2: переход №
A3: Lпр=
A4: Длина труб= | B4: =C3*B3 -> 0
A5: Адрес
A6: Дата начала | B6: =CONCATENATE(C6," ",D6," ",E6)
A7: Дата окончания | B7: =CONCATENATE(C7," ",D7," ",E7)
A8: Дата АОСР | B8: =CONCATENATE(C8," ",D8," ",E8)

Sheet АОСР (1)
AJ1: Приказ Минстроя №344/пр от 16.05.2023
AJ2: приложение №2
A3: Объект капитального строительства
A5: (наименование объекта капитального строительства в соответствии с проектной документацией, почтовый или строительный адрес объекта капитального строительства)
A6: Застройщик, технический заказчик, лицо, ответственное за эксплуатацию здания, сооружения, или региональный оператор
A8: (ФИО, адрес места жительства, ОГРНИП, ИНН индивидуального предпринимателя, полное или сокращенное наименование, ОГРН, ИНН, адрес юр. лица в пределах его нахождения, телефон или факс, полное и (или) сокращенное наименование, ОГРН, ИНН саморегулируемой организации, членом которой является указанное юридическое лицо или индивидуальный предприниматель (за исключением случаев, когда членство в саморегулируемых организациях в области, строительства, реконструкции, капитального ремонта объектов капитального строительства не требуется); ФИО, паспортные данные, адрес места жительства, телефон или факс - для физических лиц, не являющихся индивидуальными предпринимателями)
A9: Лицо, осуществляющее строительство, реконструкцию, капитальный ремонт
A11: (фамилия, имя, отчество (последнее - при наличии), адрес места жительства, ОГРНИП, ИНН индивидуального предпринимателя, полное и (или) сокращенное наименование, ОГРН, ИНН, адрес юридического лица в пределах его местонахождения, телефон или факс, полное или сокращенное наименование, ОГРН, ИНН саморегулируемой организации, членом которой является указанное юр. лицо или индивидуальный предприниматель (за исключением случаев, когда членство в саморегулируемых организациях в области строительства, реконструкции, капитального ремонта объектов капитального строительства не требуется)
A12: Лицо, осуществляющее подготовку проектной документации
A14: (ФИО, адрес места жительства, ОГРНИП, ИНН индивидуального предпринимателя, полное или сокращенное наименование, ОГРН, ИНН, адрес юр. лица в пределах его места нахождения, телефон или факс, полное и (или) сокращенное наименование, ОГРН, ИНН саморегулируемой организации, членом которой является указанное юр. лицо или индивидуальный предприниматель (за исключением случаев, когда членство в саморегулируемых организациях в области архитектурно-строительного проектирования не требуется)
A15: АКТ
A16: разбивки осей объекта капитального строительства на местности
B18: № | C18: =CONCATENATE("1 (ЗП ГНБ №",Лист1!B2,")") -> 1 (ЗП ГНБ №) | X18: " | Y18: =Лист1!C6 -> 0 | AA18: " | AB18: =Лист1!D6 -> 0 | AG18: =Лист1!E6 -> 0 | AJ18: г.
Z19: (дата составления акта)
A21: Представитель застройщика, технического заказчика, лица, ответственного за эксплуатацию здания, сооружения, или регионального оператора по вопросам строительного контроля
A23: Представитель застройщика, технического заказчика, лица, ответственного за эксплуатацию здания, сооружения | AQ23: Акимов Ю.О.
AQ24: Панин Д.А.
A25: (должность (при наличии), фамилия, инициалы, идентификационный номер в национальном реестре специалистов в области строительства (за исключением случаев, когда членство в саморегулируемых организациях в области строительства, реконструкции, капитального ремонта объектов капитального строительства не требуется), реквизиты распорядительного документа, подтверждающего полномочия, с указанием полного или сокращенного наименования, ОГРН, ИНН, адреса юр. лица в пределах его места нахождения , ФИО, адреса места жительства, ОГРНИП, ИНН индивидуального предпринимателя
A26: Представитель лица, осуществляющего строительство, реконструкцию, капитальный ремонт
A28: (должность (при наличии), фамилия, инициалы, реквизиты распорядительного документа, подтверждающего полномочия)
A29: Представитель лица, осуществляющего строительство, реконструкцию, капитальный ремонт, по вопросам строительного контроля
A31: (должность (при наличии), фамилия, инициалы, идентификационный номер в национальном реестре специалистов в области строительства (за исключением случаев, когда членство в саморегулируемых организациях в области строительства, реконструкции, капитального ремонта объектов капитального строительства не требуется), реквизиты распорядительного документа, подтверждающего полномочия)
A32: Представитель лица, осуществляющего подготовку проектной документации (в случае привлечения застройщиком лица, осуществляющего подготовку проектной документации, для проверки соответствия выполняемых работ проектной документации согласно части 2 статьи 53 Градостроительного кодекса Российской Федерации)
A34: (должность (при наличии), фамилия, инициалы, реквизиты распорядительного документа, подтверждающего полномочия, с указанием полного или сокращенного наименования, ОГРН, ИНН, адреса юр. лица в пределах его места нахождения, фамилии, имени, отчества, адреса места жительства, ОГРНИП, ИНН индивидуального предпринимателя)
A35: Представитель лица, выполнившего работы по разбивке осей объекта капитального строительства на местности (в случае выполнения работ по договорам о строительстве, реконcтрукции, капитальном ремонте объектов капитального строительства, заключенным с иными лицами)
A37: (должность (при наличии), фамилия, инициалы, реквизиты распорядительного документа, подтверждающего полномочия, с указанием полного или сокращенного наименования, ОГРН, ИНН, адреса юр. лица в пределах его места нахождения, ФИО, адреса места жительства, ОГРНИП, ИНН индивидуального предпринимателя)
A38: составили настоящий акт о том, что произведена в натуре разбивка осей
A39: =CONCATENATE("Закрытого перехода методом ГНБ №",Лист1!B2," по адресу: ",Лист1!B5,) -> Закрытого перехода методом ГНБ № по адресу:
A40: объекта капитального строительства
A41: =A4 -> 0
A42: (наименование объекта капитального строительства)
A43: При этом установлено:
A44: 1.Разбивка произведена по данным
A46: (номер, другие реквизиты чертежа, наименование проектной документации)
A47: 2. Закрепление осей произведено | N47: колышками разбивки при помощи геодезического оборудования.
A49: 3. Обозначение осей, нумерация и расположение точек соответствует проектной документации.
A51: Разбивка осей объекта капитального строительства на местности соответствует требованиям проектной документации, а также техническим регламентам (нормам и правилам), иным нормативным правовым актам
A52: =CONCATENATE(A45,", ",A41) -> , 0
A53: (номер, другие реквизиты чертежа, наименование проектной документации, сведения о лицах, осуществляющих подготовку
A54: СП 126.13330.2017 «Геодезические работы в строительстве». СНиП 3.01.03-84
...

Sheet АОСР (2)
AJ1: Приказ Минстроя №344/пр от 16.05.2023
AJ2: приложение №3
A3: Объект капитального строительства
A4: ='АОСР (1)'!A4:AJ4 -> 0
A5: (наименование объекта капитального строительства в соответствии с проектной документацией, почтовый или строительный адрес объекта капитального строительства)
A6: Застройщик, технический заказчик, лицо, ответственное за эксплуатацию здания, сооружения, или региональный оператор
A7: ='АОСР (1)'!A7:AJ7 -> 0
A8: (ФИО, адрес места жительства, ОГРНИП, ИНН индивидуального предпринимателя, полное или сокращенное наименование, ОГРН, ИНН, адрес юр. лица в пределах его нахождения, телефон или факс, полное и (или) сокращенное наименование, ОГРН, ИНН саморегулируемой организации, членом которой является указанное юридическое лицо или индивидуальный предприниматель (за исключением случаев, когда членство в саморегулируемых организациях в области, строительства, реконструкции, капитального ремонта объектов капитального строительства не требуется); ФИО, паспортные данные, адрес места жительства, телефон или факс - для физических лиц, не являющихся индивидуальными предпринимателями)
A9: Лицо, осуществляющее строительство, реконструкцию, капитальный ремонт
A10: ='АОСР (1)'!A10:AJ10 -> 0
A11: (фамилия, имя, отчество (последнее - при наличии), адрес места жительства, ОГРНИП, ИНН индивидуального предпринимателя, полное и (или) сокращенное наименование, ОГРН, ИНН, адрес юридического лица в пределах его местонахождения, телефон или факс, полное или сокращенное наименование, ОГРН, ИНН саморегулируемой организации, членом которой является указанное юр. лицо или индивидуальный предприниматель (за исключением случаев, когда членство в саморегулируемых организациях в области строительства, реконструкции, капитального ремонта объектов капитального строительства не требуется)
A12: Лицо, осуществляющее подготовку проектной документации
A13: ='АОСР (1)'!A13:AJ13 -> 0
A14: (ФИО, адрес места жительства, ОГРНИП, ИНН индивидуального предпринимателя, полное или сокращенное наименование, ОГРН, ИНН, адрес юр. лица в пределах его места нахождения, телефон или факс, полное и (или) сокращенное наименование, ОГРН, ИНН саморегулируемой организации, членом которой является указанное юр. лицо или индивидуальный предприниматель (за исключением случаев, когда членство в саморегулируемых организациях в области архитектурно-строительного проектирования не требуется)
A15: АКТ
A16: освидетельствования скрытых работ
B18: № | C18: =CONCATENATE("2 (ЗП ГНБ №",Лист1!B2,")") -> 2 (ЗП ГНБ №) | X18: " | Y18: =Лист1!C8 -> 0 | AA18: " | AB18: =Лист1!D8 -> 0 | AG18: =Лист1!E8 -> 0 | AJ18: г.
Z19: (дата составления акта)
A21: Представитель застройщика, технического заказчика, лица, ответственного за эксплуатацию здания, сооружения, или регионального оператора по вопросам строительного контроля
A22: ='АОСР (1)'!A22:AJ22 -> 0
A23: Представитель застройщика, технического заказчика, лица, ответственного за эксплуатацию здания, сооружения
A24: ='АОСР (1)'!A24:AJ24 -> 0
A25: (должность (при наличии), фамилия, инициалы, идентификационный номер в национальном реестре специалистов в области строительства (за исключением случаев, когда членство в саморегулируемых организациях в области строительства, реконструкции, капитального ремонта объектов капитального строительства не требуется), реквизиты распорядительного документа, подтверждающего полномочия, с указанием полного или сокращенного наименования, ОГРН, ИНН, адреса юр. лица в пределах его места нахождения , ФИО, адреса места жительства, ОГРНИП, ИНН индивидуального предпринимателя
A26: Представитель лица, осуществляющего строительство, реконструкцию, капитальный ремонт
A27: ='АОСР (1)'!A27:AJ27 -> 0
A28: (должность (при наличии), фамилия, инициалы, реквизиты распорядительного документа, подтверждающего полномочия)
A29: Представитель лица, осуществляющего строительство, реконструкцию, капитальный ремонт, по вопросам строительного контроля
A30: ='АОСР (1)'!A30:AJ30 -> 0
A31: (должность (при наличии), фамилия, инициалы, идентификационный номер в национальном реестре специалистов в области строительства (за исключением случаев, когда членство в саморегулируемых организациях в области строительства, реконструкции, капитального ремонта объектов капитального строительства не требуется), реквизиты распорядительного документа, подтверждающего полномочия)
A32: Представитель лица, осуществляющего подготовку проектной документации (в случае привлечения застройщиком лица, осуществляющего подготовку проектной документации, для проверки соответствия выполняемых работ проектной документации согласно части 2 статьи 53 Градостроительного кодекса Российской Федерации)
A34: (должность (при наличии), фамилия, инициалы, реквизиты распорядительного документа, подтверждающего полномочия, с указанием полного или сокращенного наименования, ОГРН, ИНН, адреса юр. лица в пределах его места нахождения, фамилии, имени, отчества, адреса места жительства, ОГРНИП, ИНН индивидуального предпринимателя)
A35: Представитель лица, выполнившего работы, подлежащие освидетельствованию (в случае выполнения работ по договорам о строительстве, реконcтрукции, капитальном ремонте объектов капитального строительства, заключенным с иными лицами)
A37: (должность (при наличии), фамилия, инициалы, реквизиты распорядительного документа, подтверждающего полномочия, с указанием полного или сокращенного наименования, ОГРН, ИНН, адреса юр. лица в пределах его места нахождения, ФИО, адреса места жительства, ОГРНИП, ИНН индивидуального предпринимателя)
A38: произвели осмотр работ, выполненных
A40: (полное и (или) сокращенное наименование или ФИО лица, выполнившего работы, подлежащие освидетельствованию)
A41: и составили настоящий акт о нижеследующем:
A42: 1. К освидетельствованию предъявлены следующие работы:
A43: =CONCATENATE("Строительство закрытого перехода №",Лист1!B2," методом ГНБ; Lпр.=",Лист1!B3," м, Lобщ.=",Лист1!B4," м, одна скважина из 2-х труб d=225 мм, по адресу : ",Лист1!B5,", проверка трубных переходов на проходимость; затягивание шнура; нумерация труб; установка заглушек.") -> Строительство закрытого перехода № методом ГНБ; Lпр.= м, Lобщ.=0 м, одна скважина из 2-х труб d=225 мм, по адресу : , проверка трубных переходов на проходимость; затягивание шнура; нумерация труб; установка заглушек.
A44: (наименование скрытых работ)
A45: 2. Работы выполнены по проектной документации
...
